## 异常使用
异常是Java语言提供的一种出错处理机制。在Java编程中，我们时刻都离不开异常。在编写正常逻辑代码的同时，我们总是需要编写处理各种异常情况的逻辑代码。不合理的使用异常会导致诸多问题，比如程序变慢，异常信息丢失。除了异常，错误码也是常用的出错处理方式。相对于错误码，异常有诸多优势，比如可以携带更多的错误信息（exception中可以有message、stack trace等信息）等。除此之外，异常可以将正常业务代码和异常处理代码分离，使得代码的可读性更好。

### Java异常相关的关键字有throw、throws、try、catch、finally。
throw用来抛出异常
throws用来在方法定义中声明方法可能抛出的异常
try用来标记需要监控异常的代码
catch用来捕获代码抛出的异常并进行处理
finally用来兜底，只要try标记的代码块被执行，不管有没有抛出异常，finally中的代码都会被执行。finally代码块一般用来做清理工作，比如关闭打开的文件等。异常使用的示例代码如下所示
~~~java
public byte[] readData(String filePath) throws DataReadException {
  InputStream in = null;
  try {
    in = new FileInputStream(filePath);
    byte[] data = new byte[in.available()];
    in.read(data);
    return data;
  } catch (FileNotFoundException e) {
    // DataReadException是自定义异常，待会会讲解
    throw new DataReadException("File not found: " + filePath, e);
  } catch (IOException e) {
    throw new DataReadException("Failed to read: " + filePath, e);
  } finally {
    if (in != null) {
      try {
        in.close();
      } catch (IOException e) {
        //使用日志框架记录日志
      }
    }
  }
}
~~~

如上代码所示，try代码块之后可以紧跟着多个catch代码块，用来捕获try代码块在执行时抛出的不同异常。需要注意的是，异常的捕获顺序应该是先捕获子类异常，再捕获父类异常，否则，捕获子类异常的代码块将不会被执行。如上代码所示，IOException是FileNotFoundException的父类，如果我们先捕获IOException异常，再捕获FileNotFoundException异常，那么，代码抛出的FileNotFoundException异常会被当做IOException异常被捕获。

除了以上基本用法之外，JDK7还为异常引入了一些新的特性。如下示例代码所示，catch可以一次性捕获多个异常。除此之外，对于实现了java.lang.AutoClosable接口的资源类，我们可以使用try-with-resources语句来实现资源的自动关闭和释放，这样我们就不需要调用finally语句来显式地关闭和释放资源，避免了忘记关闭资源而造成的资源泄露。
~~~java
public void readData(String filePath) throws DataReadException {
  try (InputStream in = new FileInputStream(filePath)) {
    Thread.sleep(10);
    ...
  } catch (FileNotFoundException | InterruptedException e) {
    ...
  } catch (IOException e) {
    throw new DataReadException("Failed to read: " + filePath, e);
  }
}
~~~

## 异常体系
Java定义了很多内建异常，Throwable是所有异常的父类。
Throwable包含两个子类：Error和Exception。
Exception又派生出了子类RuntimeException。因此，所有内建Java异常可以分为3类：继承自Error的异常、继承自Exception的异常、继承自RuntimeException的异常。

### 不同类型的异常具有不同的特点
继承自的Error的异常，是一种比较特殊的异常，用来表示程序无法处理的严重错误，这些错误有可能导致线程或JVM的终止，比如OutOfMemoryError、StackOverflowError、NoClassDefFoundError等。

继承自Exception的异常叫做受检异常（Checked Exception）或编译时异常（Compile Exception），比如IOException、FileNotFoundException、InterruptedException等。在编写代码的时候，我们需要主动去捕获或者在函数定义中声明此类异常，否则编译就会报错。

继承自RuntimeException的异常叫做非受检异常（Unchecked Exception）或者运行时异常（Runtime Exception），比如NullPointerException、ArithmeticException、ArrayIndexOutOfBoundsException等。跟编译时异常相反，在编写代码的时候，我们不需要主动捕获或在函数定义中声明此类异常。编译器在编译代码时，并不会检查代码是否有对运行时异常做了处理。

## 自定义异常
尽管Java提供了很多内建异常，但是，在平时的开发中，为了更加准确地描述异常发生的情况，我们就会自定义异常。如下代码所示，我们定义了UserNotExistingException异常，用来表示用户不存在这一异常情况，
~~~java
public class UserNotExistingException extends Exception {
  public UserNotExistingException() {
    super();
  }

  public UserNotExistingException(String msg, Throwable cause) {
    super(msg, cause);
  }

  public UserNotExistingException(String msg) {
    super(msg);
  }

  public UserNotExistingException(Throwable cause) {
    super(cause);
  }
}
~~~

自定义异常跟大多数内建异常一样，要么作为受检异常继承自Exception，要么作为非受检异常继承自RuntimeException。那么，具体该如何选择呢？

对于代码bug（比如数组越界）以及不可恢复异常（比如数据库连接失败），即便我们对异常进行了捕获也无法挽救，因此，我们倾向于使用非受检异常。对于可恢复异常、业务异常、预期可能发生的异常，比如提现金额大于余额的异常，我们更倾向于使用受检异常。

不过，在平时的项目的开发中，我们几乎都是依赖框架来编程，即业务逻辑运行在框架中。对于程序员自定义的异常，不管是受检异常还是非受检异常，在大部分情况下都会被框架兜底捕获并处理，并不会直接导致程序的终止。从这个角度上来看，在编写业务代码时，业务异常定义为受检异常和非受检异常的差别不大。不过，受检异常一直被人诟病。有些人主张所有的异常情况都应该使用非受检异常。支持这种观点的理由主要有以下三个。

1. 受检异常需要显式地在函数定义中声明。如果函数的代码逻辑有可能抛出很多受检异常，那么，函数定义会非常冗长，如下示例函数所示，函数使用起来也不方便，而且还会影响代码的可读性。
~~~java
public long buy() throws UserNotFoundException,    
                         UserHasNoEnoughMoneyException,
                         DuplicatedBuyException,
                         NoEnoughNotesException,
                         UserHasNoPermissionToBuyException;
~~~

2. 受检异常的处理比较繁琐。当使用如上示例函数时，我们需要显示的捕获每个异常或者在函数定义中重复声明。而非受检异常正好相反，我们不需要在函数定义中显示声明，并且是否需要捕获处理，也可以自由决定。

3. 受检异常的使用违反开闭原则。如果我们给某个函数新增一个受检异常，那么，调用这个函数的上游函数都需要做相应的代码修改，直到某个函数将这个新增的异常捕获处理不再抛出为止。相反，使用非受检异常可以减少代码的改动范围。我们可以灵活地选择在某个函数中集中处理非受检异常，比如，在Spring中的AOP切面中集中处理异常。

不过，非受检异常也有弊端，它的优点其实也正是它的缺点。从刚刚的表述中，我们可以看出，非受检异常使用起来更加灵活，怎么处理异常的主动权交给了程序员。过于灵活会带来不可控，一些本应该捕获处理的异常就有可能被程序员遗漏。除此之外，因为非受检异常不需要显式地在函数定义中声明，所以，在使用函数时，我们就需要查看函数的实现代码，才能知道函数具体会抛出哪些异常。

对于应该使用受检异常还是非受检异常，争论有很多，但并不存在一个非常强有力的理由能够说明一个就一定比另一个更好。在平时开发中，我们只需要根据团队的开发习惯，在同一个项目中，制定统一的异常处理规范即可。

## 异常处理
当程序抛出异常时，我们应该如何处理抛出的异常呢？一般来讲，我们有3种处理方法：捕获后记录日志、原封不动再抛出、包装成新异常抛出。示例代码如下所示。

1. 捕获后记录日志
~~~java
public void f() throws LowLevelException { ... }
public void g() {
  try {
    f();
  } catch(LowLevelException e) {
    log.warn("...", e); //使用日志框架记录日志
  }
}
~~~

2. 原封不动再抛出
~~~java
public void f() throws LowLevelException { ... }
//如果LowLevelException是非受检异常，则不需要在函数g()定义中声明
public void g() throws LowLevelException {
  f();
}
~~~

3. 包装成新异常抛出
~~~java
public void f() throws LowLevelException { ... }
public void g() {
  try {
    f();
  } catch(LowLevelException e) {
    throw new HighLevelException("...", e);
  }
}
~~~

当代码抛出异常时，选择以上哪种处理方法，有一个重要的参考原则，那就是：函数只抛出跟函数所涉及业务相关的异常。
在函数内部，如果某块代码的异常行为，并不会导致调用此函数的上层代码出现异常行为，也就是说，上层代码并不关心被调用函数内部的这个异常，我们就可以在函数内部将这个异常“消化掉”，即将其捕获并打印日志记录。
如果函数内部的异常行为会导致调用此函数的上层代码出现异常行为，那么，我们就必须让上层代码感知到此异常的存在。如果此异常跟函数的业务相关，上层代码在调用此函数时，知道如何处理此异常，那么，函数直接将此异常抛出就可。
如果此异常跟函数的业务无关，上层代码无法理解这个异常的含义，不知道如何处理，那么，我们就需要将此异常包裹成新的跟函数业务相关的异常再抛出。我们拿如下代码来进一步解释刚刚的阐述。
~~~java
public byte[] readData(String filePath) throws DataReadException,FileNotFoundException {
  InputStream in = null;
  try {
    Thread.sleep(10);
    in = new FileInputStream(filePath);
    byte[] data = new byte[in.available()];
    in.read(data);
    return data;
  } catch (InterruptedException e) {
    throw new DataReadException("Interrupted when reading: " + filePath, e);
  } catch (IOException e) {
    throw new DataReadException("Failed to read: " + filePath, e);
  } finally {
    if (in != null) {
      try {
        in.close();
      } catch (IOException e) {
        //使用日志框架记录日志
      }
    }
  }
}
~~~

参照刚刚给出的3种异常处理方式以及选择原则，我们来分析一下上面的代码。
1. 对于文件关闭失败（对应in.close()语句）导致的IOException异常，调用readData()函数的上层代码并不关心，因此，我们直接将其捕获并打印日志。
2. 对于文件读取失败而抛出的IOException异常，因为IOException异常比较底层，如果我们原封不动将其抛出，那么，上层代码可能并不知道如何处理。因此，我们将其重新包裹成自定义的DataReadException异常再抛出。
3. 同理，对于因sleep()函数被中断而抛出的InterruptedException异常，上层代码也无法理解，因此，我们同样将其包裹为DataReadException异常再抛出。
4. 对于文件打开失败而抛出的FileNotFoundException异常，因为跟readData()函数业务相关，毕竟readData()函数中的参数就是文件的路径，所以，我们可以直接将其抛出。当然，如果我们想要减少readData()函数受检异常的个数，那么也可以将FileNotFoundException异常统一包裹为DataReadException异常再抛出。

## 异常调用链
异常最终的宿命终究是被捕获并记录异常信息，以便程序员debug问题。为了给程序员展示充足的异常信息，我们一般需要将整个异常调用链完整打印出来。异常调用链跟函数调用链类似，记录异常发生的整个过程，即从当前捕获的异常一直追溯到引起这个异常的最起初的异常为止。我们举个例子来看下，如下代码所示。
~~~java
public class Demo17_1 {
  public static class LowLevelException extends Exception {
    public LowLevelException() { super(); }
    public LowLevelException(String msg, Throwable cause) { super(msg, cause); }
    public LowLevelException(String msg) { super(msg); }
    public LowLevelException(Throwable cause) { super(cause); }
  }

  public static class MidLevelException extends Exception {
    //...与LowLevelException实现类似，省略代码实现...
  }

  public static class HighLevelException extends RuntimeException {
    //...与LowLevelException实现类似，省略代码实现...
  }

  public static void fa() throws LowLevelException {
    throw new LowLevelException("LowLevelException-msg");
  }

  public static void fb() throws LowLevelException {
    fa();
  }

  public static void fc() throws MidLevelException {
    try {
      fb();
    } catch (LowLevelException e) {
      throw new MidLevelException("MidLevelException-msg", e);
    }
  }

  public static void fd() {
    try {
      fc();
    } catch (MidLevelException e) {
      throw new HighLevelException("HighLevelException-msg", e);
    }
  }

  public static void fe() {
      fd();
  }
  
  public static void main(String[] args) {
    try {
      fe();
    } catch(HighLevelException e) {
      e.printStackTrace();
    }
  }
}
~~~

分析一下上述代码

LowLevelException异常为调用链中的第一个异常，在fa()函数中创建。fb()函数未捕获此异常并直接将其抛出。fc()函数将此异常捕获并且重新包装成MidLevelException异常抛出，因此，LowLevelException异常的生命周期经历了3个函数：fa()、fb()、fc()。

MidLevelException异常在fc()函数中创建，在fd()函数中被捕获，然后重新包装成HighLevelException异常抛出。因此，MidLevelException()异常的生命周期经历了2个函数：fc()和fd()。

HighLevelException异常为运行时异常，在fd()函数中创建。fe()函数没有将其捕获，默认原样抛出。最终main()函数将其捕获并输出异常调用链信息，至此异常调用链结束。因此，HighLevelException异常的生命周期经历了3个函数：fd()、fe()、main()。

HighLevelException异常由MidLevelException异常引起，MidLevelException异常又由LowLevelException异常引起，因此，上述代码打印出来的异常调用链，如下所示。
~~~java
demo.Demo17_1$HighLevelException: HighLevelException-msg
	at demo.Demo17_1.fd(Demo17_1.java:53)
	at demo.Demo17_1.fe(Demo17_1.java:58)
	at demo.Demo17_1.main(Demo17_1.java:27)
Caused by: demo.Demo17_1$MidLevelException: MidLevelException-msg
	at demo.Demo17_1.fc(Demo17_1.java:45)
	at demo.Demo17_1.fd(Demo17_1.java:51)
	... 2 more
Caused by: demo.Demo17_1$LowLevelException: LowLevelException-msg
	at demo.Demo17_1.fa(Demo17_1.java:34)
	at demo.Demo17_1.fb(Demo17_1.java:38)
	at demo.Demo17_1.fc(Demo17_1.java:43)
	... 3 more
~~~

需要特别注意的是，当捕获异常并包裹成新的异常抛出时，我们一定要将先前的异常通过cause参数传递进新的异常，否则，异常调用链将会被断开。比如，对于上述示例代码，在创建MidLevelException异常时，如果我们没有将LowLevelException异常通过cause参数传递给MidLevelException异常，那么，通过MidLevelException异常将无法追踪到LowLevelException异常。最终打印出来的异常调用链将只包含HighLevelException异常信息和MidLevelException异常信息。
~~~java
//错误做法
try {
  ...
} catch (CausedByException e) {
  throw new NewException("msg..."); // e丢失
}

//正确的做法
try {
  ...
} catch (CausedByException e) {
  throw new NewException("msg...", e);
}
~~~

在平时的开发中，我们还需要特别注意，对于异常的处理，要么记录，要么抛出，两者不能同时执行。错误的做法如下所示。在异常调用链中，我们只需要在异常生命周期结束时，打印异常调用链即可，不需要每次抛出异常时都记录异常，否则，将会导致异常调用链的重复打印。
~~~java
//错误的做法
try {
  ...
} catch (CausedByException e) {  
   logger.error("...", e);
   throw new NewException("msg...", e);
}
~~~

## 异常实现原理
一般来讲，程序有3种执行结构：顺序、分支和循环，而异常的运行机制却非常特别，不符合这3种执行结构。不管try监听的代码块有没有异常抛出，finally代码块总是被执行，并且，在finally代码执行完成之后，try代码块和catch代码块中的return语句才会被执行。

JVM在生成字节码时，会将finally代码块内联（也就是插入）到try代码块和catch代码块中的return语句之前，这样就可以实现不管程序是否抛出异常，finally代码块总是会在函数返回之间执行。

在finally代码块中添加return语句，如下所示。改造之后的这段代码的运行结果是什么呢？
~~~java
public class Demo {
  public static void main(String[] args) {
    double res = div(2, 1);
    System.out.println(res);
    res = div(2, 0);
    System.out.println(res);
  }

  public static double div(int a, int b) {
    try {
      double res = a / b;
      System.out.println("in try block.");
      return res;
    } catch(ArithmeticException e) {
      System.out.println("in ATE catch block.");
      return -1.0;
    } finally {
      System.out.println("in finally block.");
      return -2.0; //额外添加了这一行
    }
  }
}
~~~
上述代码的运行结果如下所示。不管try代码块中的代码是正常运行还是抛出异常，div()函数的返回值总是-2.0，也就是说，执行完finally代码块中的return语句之后，函数就返回了，JVM没有机会再执行try或catch代码块中的return语句。实际上，如果我们把finally代码块中的return语句改为throw语句，效果也是一样的。因此，在平时的开发中，我们切记不要在finally代码块中使用return语句和throw语句，否则，try和catch代码块中的return和throw将不会被执行。
~~~
//div(2, 1)
in try block.
in finally block.
-2.0
//div(2, 0)
in ATE catch block.
in finally block.
-2.0
~~~

## 异常性能分析
很多人都有这样的认识：异常会导致程序变慢，那么，为什么异常会导致程序变慢呢？

如果try代码块没有抛出异常，那么，JVM就不会去搜索异常表，也不会执行catch代码块，程序正常执行结束，其运行轨迹跟代码没有try-catch语句包裹时的运行轨迹基本相同。除此之外，异常表、异常兜底字节码、finally内联都是在编译时生成的，不会占用运行时间。也就是说，如果程序未抛出异常，那么程序的性能完全不会因为try-catch语句的引入而下降。异常导致程序变慢的情况，只发生在异常被抛出时。当一个异常被抛出时，程序中一般会额外增加这样三个操作：使用new创建异常、使用throw抛出异常、打印异常调用链。

### 使用new创建异常
使用new创建异常的过程，主要包含两部分工作。第一部分工作是在堆上创建异常对象，并初始化对象的成员变量。这部分工作跟创建其他类型的对象没有区别。第二部分工作是调用Throwable中的fillStackTrace()函数生成栈追踪信息。

栈追踪信息指的是当创建异常时函数调用栈中的所有函数的信息。栈追踪信息记录了异常产生的整个函数调用链路，方便程序员定位此异常是如何产生的。我们举个例子来解释一下。示例如下代码所示。
~~~java
public class Demo {
  public static void main(String[] args) {
    fe();
  }
  public static void fe() { fd(); }
  public static void fd() { fc(); }
  public static void fc() { fb(); }
  public static void fb() { fa(); }
  public static void fa() {
    throw new RuntimeException("oops!");
  }
}
~~~
当fa()函数通过new创建RuntimeException异常时，函数调用栈中将包含当前线程执行位置的所有函数栈帧

fillStackTrace()函数所做的工作就是遍历函数调用栈，将每个函数的信息存入异常的stackTrace成员变量中。stackTrace成员变量的定义如下所示。
~~~java
private StackTraceElement[] stackTrace;
// stackTrace为StackTraceElement类型的数组，StackTraceElement的定义如下所示，其成员变量有4个，分别是函数所属类名、函数名、函数所属类文件名，以及异常抛出时，此函数执行到了哪一行。

public final class StackTraceElement {
    private String declaringClass;
    private String methodName;
    private String fileName;
    private int    lineNumber;
    //...省略其他代码...
}
~~~

可以通过异常对象的getStackTrace()函数，将异常的stackTrace栈追踪信息打印出来，如下代码所示。
~~~java
public class Demo {
  public static void main(String[] args) {
    fe();
  }
  public static void fe() { fd(); }
  public static void fd() { fc(); }
  public static void fc() { fb(); }
  public static void fb() { fa(); }
  public static void fa() {
    RuntimeException e = new RuntimeException("oops!");
    
    // 打印strackTrace
    StackTraceElement[] stackTrace = e.getStackTrace();
    for (StackTraceElement element : stackTrace) {
      System.out.println(element);
    }
    
    throw e;
  }
}
~~~

上述代码的打印结果如下所示。
~~~java
demo.Demo17_3.fa(Demo17_3.java:18)
demo.Demo17_3.fb(Demo17_3.java:16)
demo.Demo17_3.fc(Demo17_3.java:15)
demo.Demo17_3.fd(Demo17_3.java:14)
demo.Demo17_3.fe(Demo17_3.java:13)
demo.Demo17_3.main(Demo17_3.java:6)
~~~

如果函数调用栈的深度比较小，如上示例代码所示，只包含5个函数的栈帧，那么fillStackTrace()生成栈追踪信息的耗时也会比较少，但是，对于大部分项目来说，业务代码往往都运行在容器（比如Tomcat）、框架（比如Dubbo、Spring）中。尽管业务代码的函数调用层次不会很深，但累加上容器中函数调用和框架中的函数调用，总的函数调用层次就有可能很深。在这种情况下，fillStackTrace()的耗时就相当可观了。这就是异常导致程序变慢的其中一个非常重要的原因。

特别是在递归中抛出异常，如果递归调用层次比较深，那么对应的函数调用栈也会非常深，其中可能包含上千个函数栈帧，那么，执行fillStackTrace()函数将会非常耗时。因此，在递归中不要轻易抛出异常。

### 使用throw抛出异常

当异常创建完成之后，我们一般会紧接着将其抛出，示例代码如下所示。
~~~java
public static void fa() {
    ...
    throw new RuntimeException("oops!");  //第3行代码
}
~~~

当函数执行throw语句抛出异常时，JVM底层会执行“栈展开（stack unwinding）”，依次将函数调用栈中的函数栈帧弹出，直到查找到哪个函数可以捕获这个异常为止。我们举个例子解释一下，示例代码如下所示。
~~~java
public class Demo17_4 {
  public static void main(String[] args) {
    fe();
  }
  public static void fe() { fd(); }
  public static void fd() { //捕获处理
    try {
      fc();
    } catch(Exception e) {
      System.out.println("I catch you!");
    }
  }
  public static void fc() { fb(); }
  public static void fb() { fa(); }
  public static void fa() { //抛出异常
    throw new RuntimeException("oops!");
  }
}
~~~

当fa()函数执行throw语句抛出异常时，JVM将执行栈展开，依次检查函数调用栈中栈帧对应的函数的字节码，发现fa()、fb()、fc()这三个函数均没有捕获此异常，因此，对应的栈帧依次弹出函数调用栈。当JVM检查到fd()函数时，发现fd()函数捕获了fa()函数抛出的异常，于是，停止栈帧弹出栈，JVM从fd()函数开始继续执行。

相对于普通的函数返回（调用return语句）导致的栈帧弹出，调用throw语句导致的栈展开除了包含栈帧弹出之外，还增加了额外的操作，即在函数的异常表中查找是否有可匹配的处理规则。如果异常抛出之后，经过很多函数调用，最终才被捕获，那么，查询这些函数的异常表的耗时就会比较多。这就是异常导致程序变慢的另一个原因。

很多人喜欢使用Spring AOP，在程序运行的很外层，捕获所有的异常，实际上这样的做法增加了栈展开的耗时。不过，权衡性能和开发的便利性，在没有大量异常抛出的情况下，这样做也是可行的。

### 打印异常调用链

异常最终的归宿是被捕获并记录。记录异常也是异常使用过程中一个耗时环节。

通过printStackTrace()函数记录异常信息的方式并不常用，因为此函数将异常信息输出到标准出错中，异常信息无法被保存以便反复查看。常见的异常记录方式是使用日志框架来记录异常信息。实际上，使用日志框架记录异常和使用printStackTrace()记录异常的主要区别是输出的目的地不同，但生成的异常调用链信息基本一致，都包含整个异常调用链上各个异常之间的caused by关系，以及每个异常的栈追踪信息。

## 异常最佳实践
尽管异常的创建、抛出、打印都会消耗一定的时间，但是，少量异常并不会导致程序明显变慢。只有在极端情况下，比如，在项目中，我们定义了大量的较常发生的业务异常，比如查询用户不存在时抛出UserNotExistingException异常。在高并发的情况下，这类业务异常就有可能频繁发生，进而触发大量异常的创建、抛出和打印，最终导致程序明显变慢。

例如限流框架。当访问被限流时，限流框架抛出OverloadException异常。当促销活动导致业务系统流量暴增时，限流框架在生效的同时，也不幸导致了业务系统的宕机。最后，我追踪发现，这个问题就是由异常引起。当大量访问被限流时，线程会大量创建、抛出、打印OverloadException异常，从而导致整个系统响应变慢甚至超时。那么，怎么来解决这个问题呢？

实际上，对于OverloadException业务异常，其作用更像是错误码，我们没必要记录stackTrace栈追踪信息，只需要将一些有用的信息记录在异常的detailMessage成员变量和cause成员变量中即可。我们可以调用Throwable中特殊的构造函数，禁止在创建异常的同时调用fillStackTrace()函数来生成stackTrace栈追踪信息。
~~~java
public class OverloadException extends Throwable {
  public OverloadException() {
    super(null,null, true, false);
  }
  
  public OverloadException(String msg, Throwable cause) {
    super(msg, cause, true, false);
  }
  
  public OverloadException(String msg) {
    super(msg, null, true, false);
  }
  
  public OverloadException(Throwable cause) {
    super(null, cause, true, false);
  }
}

//Throwable的特殊构造函数
protected Throwable(String message, Throwable cause,
                    boolean enableSuppression,
                    boolean writableStackTrace) {
    if (writableStackTrace) {
        fillInStackTrace();
    } else {
        stackTrace = null;
    }
    detailMessage = message;
    this.cause = cause;
    if (!enableSuppression)
        suppressedExceptions = null;
}
~~~

如上代码所示，没有了生成stackTrace栈追踪信息的过程，异常的创建过程就普通对象的创建过程无异了。同时，为了避免大量异常日志的打印，我们禁止掉了限流异常OverloadException的日志输出。而抛出异常时触发的栈展开耗时，相比异常创建和打印耗时，要小很多。于是，通过优化异常的创建、抛出、打印过程，就成功解决了在高并发下，程序中大量业务异常导致程序变慢的问题。

注意下面的案例代码 finally代码块不会被执行，而是直接在catch代码块抛出异常终止程序
~~~java
public static void main(String[] args) {
    try {
        double res = 1 / 0;
        System.out.println("in try block.");
        return;
    } catch(ArithmeticException e) {
        System.out.println("in ATE catch block.");
        throw new RuntimeException("whoiam");
    } finally {
        System.out.println("in finally block.");
    }
}
~~~


